# try
```python
try:
    print('try...')
    r = 10 / 0
    print('result:', r)
except ZeroDivisionError as e:
    print('except:', e)
finally:
    print('finally...')
print('END')
```
Python的错误其实也是class，所有错误类型都继承自`BaseException`  

```python
# 用except时需要注意的是，它不但捕获该类型的错误，还把其子类也“一网打尽”
try:
    foo()
except ValueError as e:
    print('ValueError')
except UnicodeError as e:
    print('UnicodeError')

# 第二个except永远也捕获不到UnicodeError，因为UnicodeError是ValueError的子类，如果有，也被第一个except给捕获了。
```

使用 try...except 还可以跨越多层调用，如子函数报错上级函数也可以捕获


```python
# 分析错误的调用栈信息，来定位错误的位置
python3 err.py
Traceback (most recent call last):
  File "err.py", line 11, in <module>
    main()
  File "err.py", line 9, in main
    bar('0')
  File "err.py", line 6, in bar
    return foo(s) * 2
  File "err.py", line 3, in foo
    return 10 / int(s)
ZeroDivisionError: division by zero
```


# 记录错误
Python内置的`logging`模块可以非常容易地记录错误信息：
```python
# err_logging.py

import logging

def foo(s):
    return 10 / int(s)

def bar(s):
    return foo(s) * 2

def main():
    try:
        bar('0')
    except Exception as e:
        logging.exception(e) # 这样可以打印出错误堆栈，也可以让代码继续执行下去

main()
print('END')
```
